No changes detected
Operations to perform:
  Apply all migrations: admin, auth, contenttypes, materiais, notas, requisicoes, sessions
Running migrations:
Traceback (most recent call last):
  File "/home/ricardo/projetos/almoxarifado/venv_ricardo/lib/python3.12/site-packages/django/db/backends/utils.py", line 103, in _execute
    return self.cursor.execute(sql)
           ^^^^^^^^^^^^^^^^^^^^^^^^
psycopg2.errors.InsufficientPrivilege: permission denied for schema public
LINE 1: CREATE TABLE "django_migrations" ("id" bigint NOT NULL PRIMA...
                     ^


The above exception was the direct cause of the following exception:

Traceback (most recent call last):
  File "/home/ricardo/projetos/almoxarifado/venv_ricardo/lib/python3.12/site-packages/django/db/migrations/recorder.py", line 78, in ensure_schema
    editor.create_model(self.Migration)
  File "/home/ricardo/projetos/almoxarifado/venv_ricardo/lib/python3.12/site-packages/django/db/backends/base/schema.py", line 512, in create_model
    self.execute(sql, params or None)
  File "/home/ricardo/projetos/almoxarifado/venv_ricardo/lib/python3.12/site-packages/django/db/backends/postgresql/schema.py", line 45, in execute
    return super().execute(sql, params)
           ^^^^^^^^^^^^^^^^^^^^^^^^^^^^
  File "/home/ricardo/projetos/almoxarifado/venv_ricardo/lib/python3.12/site-packages/django/db/backends/base/schema.py", line 204, in execute
    cursor.execute(sql, params)
  File "/home/ricardo/projetos/almoxarifado/venv_ricardo/lib/python3.12/site-packages/django/db/backends/utils.py", line 122, in execute
    return super().execute(sql, params)
           ^^^^^^^^^^^^^^^^^^^^^^^^^^^^
  File "/home/ricardo/projetos/almoxarifado/venv_ricardo/lib/python3.12/site-packages/django/db/backends/utils.py", line 79, in execute
    return self._execute_with_wrappers(
           ^^^^^^^^^^^^^^^^^^^^^^^^^^^^
  File "/home/ricardo/projetos/almoxarifado/venv_ricardo/lib/python3.12/site-packages/django/db/backends/utils.py", line 92, in _execute_with_wrappers
    return executor(sql, params, many, context)
           ^^^^^^^^^^^^^^^^^^^^^^^^^^^^^^^^^^^^
  File "/home/ricardo/projetos/almoxarifado/venv_ricardo/lib/python3.12/site-packages/django/db/backends/utils.py", line 100, in _execute
    with self.db.wrap_database_errors:
  File "/home/ricardo/projetos/almoxarifado/venv_ricardo/lib/python3.12/site-packages/django/db/utils.py", line 91, in __exit__
    raise dj_exc_value.with_traceback(traceback) from exc_value
  File "/home/ricardo/projetos/almoxarifado/venv_ricardo/lib/python3.12/site-packages/django/db/backends/utils.py", line 103, in _execute
    return self.cursor.execute(sql)
           ^^^^^^^^^^^^^^^^^^^^^^^^
django.db.utils.ProgrammingError: permission denied for schema public
LINE 1: CREATE TABLE "django_migrations" ("id" bigint NOT NULL PRIMA...
                     ^


During handling of the above exception, another exception occurred:

Traceback (most recent call last):
  File "/home/ricardo/projetos/almoxarifado/manage.py", line 22, in <module>
    main()
  File "/home/ricardo/projetos/almoxarifado/manage.py", line 18, in main
    execute_from_command_line(sys.argv)
  File "/home/ricardo/projetos/almoxarifado/venv_ricardo/lib/python3.12/site-packages/django/core/management/__init__.py", line 442, in execute_from_command_line
    utility.execute()
  File "/home/ricardo/projetos/almoxarifado/venv_ricardo/lib/python3.12/site-packages/django/core/management/__init__.py", line 436, in execute
    self.fetch_command(subcommand).run_from_argv(self.argv)
  File "/home/ricardo/projetos/almoxarifado/venv_ricardo/lib/python3.12/site-packages/django/core/management/base.py", line 416, in run_from_argv
    self.execute(*args, **cmd_options)
  File "/home/ricardo/projetos/almoxarifado/venv_ricardo/lib/python3.12/site-packages/django/core/management/base.py", line 460, in execute
    output = self.handle(*args, **options)
             ^^^^^^^^^^^^^^^^^^^^^^^^^^^^^
  File "/home/ricardo/projetos/almoxarifado/venv_ricardo/lib/python3.12/site-packages/django/core/management/base.py", line 107, in wrapper
    res = handle_func(*args, **kwargs)
          ^^^^^^^^^^^^^^^^^^^^^^^^^^^^
  File "/home/ricardo/projetos/almoxarifado/venv_ricardo/lib/python3.12/site-packages/django/core/management/commands/migrate.py", line 353, in handle
    post_migrate_state = executor.migrate(
                         ^^^^^^^^^^^^^^^^^
  File "/home/ricardo/projetos/almoxarifado/venv_ricardo/lib/python3.12/site-packages/django/db/migrations/executor.py", line 107, in migrate
    self.recorder.ensure_schema()
  File "/home/ricardo/projetos/almoxarifado/venv_ricardo/lib/python3.12/site-packages/django/db/migrations/recorder.py", line 80, in ensure_schema
    raise MigrationSchemaMissing(
django.db.migrations.exceptions.MigrationSchemaMissing: Unable to create the django_migrations table (permission denied for schema public
LINE 1: CREATE TABLE "django_migrations" ("id" bigint NOT NULL PRIMA...
                     ^
)
